<?xml version='1.0'?>
<sdf version='1.5'>
  <model name='tergeo'>

    <!-- body -->
    <link name='base_link'>
      <pose>0 0 0.01 0 0 0</pose>

      <!-- body -->
      <visual name='base_visual'>
        <pose>0.06 -0.01 0.0 0 0 0</pose>
        <geometry>
          <mesh>
            <scale>1 1 1</scale>
            <!-- see details in element <export> in package.xml -->
            <uri>model://model_turtlebot/meshes/sc65b.dae</uri>
          </mesh>
        </geometry>
        <material>
          <!-- Gazebo/Orange -->
          <ambient>1 0.5088 0.0468 1</ambient>
          <diffuse>1 0.5088 0.0468 1</diffuse>
          <specular>0.5 0.5 0.5 128</specular>
        </material>
      </visual>

      <collision name='body_collision'>
        <pose>-0.032 0 0.080 0 0 0</pose>
        <geometry>
          <box>
            <size>0.140 0.140 0.143</size>
          </box>
        </geometry>
      </collision>

      <inertial>
        <pose>0 0 0 0 0 0</pose>
        <mass>8.2573504e-01</mass>
        <inertia>
          <ixx>2.2124416e-03</ixx>
          <iyy>2.1193702e-03</iyy>
          <izz>2.0064271e-03</izz>
          <ixy>-1.2294101e-05</ixy>
          <ixz>3.4938785e-05</ixz>
          <iyz>-5.0120904e-06</iyz>
        </inertia>
      </inertial>
    </link>
    
    <!-- left wheel joint -->
    <joint name='left_wheel_joint' type='revolute'>
      <parent>base_link</parent>
      <child>left_wheel_link</child>
      <axis>
        <use_parent_model_frame>true</use_parent_model_frame>
        <xyz>0 1 0</xyz>
      </axis>
    </joint>

    <!-- left wheel link -->
    <link name='left_wheel_link'>
      <pose>0.0 0.08 0.033 -1.570796326 0 0</pose>
      <visual name='left_wheel_visual'>
        <pose>0.0 0.0 0.0 1.570796326 0.0 0.0</pose>
        <geometry>
          <mesh> 
            <scale>0.001 0.001 0.001</scale>
            <uri>model://model_turtlebot/meshes/wheels/left_tire.stl</uri>
          </mesh>
        </geometry>
        <material>
          <ambient> 0 1 0 </ambient>
          <diffuse> 0 1 0 </diffuse>
          <specular> 0.1 0.1 0.1 1 1 </specular>
        </material>
      </visual>

      <collision name='left_wheel_collision'>
        <pose>0 0 0 0 0 0</pose>
        <geometry>
          <cylinder>
            <radius>0.033</radius>
            <length>0.018</length>
          </cylinder>
        </geometry>
        <surface>
          <friction>
            <ode>
              <mu>0.1</mu>
              <mu2>0.1</mu2>
              <fdir1>1 0 0</fdir1>
            </ode>
          </friction>
          <contact>
            <ode>
              <kp>500000.000000</kp>
              <kd>10.000000</kd>
              <max_vel>0.1</max_vel>
              <min_depth>0.001</min_depth>
            </ode>
          </contact>
        </surface>
      </collision>

      <inertial>
        <pose>0 0 0 0 0 0</pose>
        <mass>2.8498940e-02</mass>
        <inertia>
          <ixx>1.1175580e-05</ixx>
          <iyy>1.1192413e-05</iyy>
          <izz>2.0712558e-05</izz>
          <ixy>-4.2369783e-11</ixy>
          <ixz>-5.9381719e-09</ixz>
          <iyz>-1.4400107e-11</iyz>
        </inertia>
      </inertial>
    </link>

    <!-- right wheel joint -->
    <joint name='right_wheel_joint' type='revolute'>
      <parent>base_link</parent>
      <child>right_wheel_link</child>
      <axis>
        <use_parent_model_frame>true</use_parent_model_frame>
        <xyz>0 1 0</xyz>
      </axis>
    </joint>

    <!-- right wheel link -->
    <link name='right_wheel_link'>
      <pose>0.0 -0.08 0.033 -1.570796326 0 0</pose>
      <visual name='right_wheel_visual'>
        <pose>0.0 0.0 0.0 1.570796326 0.0 0.0</pose>
        <geometry>
          <mesh> 
            <scale>0.001 0.001 0.001</scale>
            <uri>model://model_turtlebot/meshes/wheels/right_tire.stl</uri>
          </mesh>
        </geometry>
        <material>
          <ambient> 0 1 0 </ambient>
          <diffuse> 0 1 0 </diffuse>
          <specular> 0.1 0.1 0.1 1 1 </specular>
        </material>
      </visual>

      <collision name='right_wheel_collision'>
        <pose>0 0 0 0 0 0</pose>
        <geometry>
          <cylinder>
            <radius>0.033</radius>
            <length>0.018</length>
          </cylinder>
        </geometry>
        <surface>
          <friction>
            <ode>
              <mu>0.1</mu>
              <mu2>0.1</mu2>
              <fdir1>1 0 0</fdir1>
            </ode>
          </friction>
          <contact>
            <ode>
              <kp>500000.000000</kp>
              <kd>10.000000</kd>
              <max_vel>0.1</max_vel>
              <min_depth>0.001</min_depth>
            </ode>
          </contact>
        </surface>
      </collision>

      <inertial>
        <pose>0 0 0 0 0 0</pose>
        <mass>2.8498940e-02</mass>
        <inertia>
          <ixx>1.1175580e-05</ixx>
          <iyy>1.1192413e-05</iyy>
          <izz>2.0712558e-05</izz>
          <ixy>-4.2369783e-11</ixy>
          <ixz>-5.9381719e-09</ixz>
          <iyz>-1.4400107e-11</iyz>
        </inertia>
      </inertial>
    </link>
    
    <!-- model plugin  -->
    <!-- diff drive plugin -->
    <plugin name="tergeo_controller" filename="libgazebo_ros_diff_drive.so">
      <commandTopic>cmd_vel</commandTopic>
      <odometryTopic>odom</odometryTopic>
      <odometryFrame>odom</odometryFrame>
      <odometrySource>world</odometrySource>
      <publishOdomTF>true</publishOdomTF>
      <robotBaseFrame>world</robotBaseFrame>
      <publishWheelTF>false</publishWheelTF>
      <publishTf>true</publishTf>
      <publishWheelJointState>true</publishWheelJointState>
      <legacyMode>false</legacyMode>
      <updateRate>30</updateRate>
      <leftJoint>left_wheel_joint</leftJoint>
      <rightJoint>right_wheel_joint</rightJoint>
      <wheelSeparation>0.160</wheelSeparation>
      <wheelDiameter>0.066</wheelDiameter>
      <wheelAcceleration>1</wheelAcceleration>
      <wheelTorque>10</wheelTorque>
      <rosDebugLevel>na</rosDebugLevel>
    </plugin>
    
    <!-- caster joint -->
    <joint name='caster_joint' type='fixed'>
      <parent>base_link</parent>
      <child>caster_link</child>
    </joint>

    <!-- caster link -->
    <link name='caster_link'>
      <pose>-0.081 0.0 0.006 -1.570796326 0 0</pose>
      <visual name='caster_visual'>
        <pose>0 0 0 0 0 0</pose>
        <geometry>
          <box>
            <size>0.030 0.009 0.020</size>
          </box>
        </geometry>
        <material>
          <ambient> 1 1 0 1 </ambient>
          <diffuse> 1 1 0 1 </diffuse>
          <specular> 0 0 0 0 0 </specular>
        </material>
      </visual>

      <collision name='caster_collision'>
        <pose>0 0 0 0 0 0</pose>
        <geometry>
          <box>
            <size>0.030 0.009 0.020</size>
          </box>
        </geometry>
        <surface>
          <friction>
            <ode>
              <mu>0.1</mu>
              <mu2>0.1</mu2>
            </ode>
          </friction>
          <contact>
            <ode>
              <kp>1000000.000000</kp>
              <kd>100.000000</kd>
              <max_vel>1.0</max_vel>
              <min_depth>0.001</min_depth>
            </ode>
          </contact>
        </surface>
      </collision>

      <inertial>
        <pose>0 0 0 0 0 0</pose>
        <mass>0.010</mass>
        <inertia>
          <ixx>0.002</ixx>
          <iyy>0.002</iyy>
          <izz>0.002</izz>
        </inertia>
      </inertial>
    </link>
    
    <!-- lidar joint  -->
    <joint name='lidar_joint' type='fixed'>
      <parent>base_link</parent>
      <child>lidar_link</child>
    </joint>

    <!-- lidar link -->
    <link name="lidar_link">
      <pose>-0.017 0 1.0 0 0 0</pose>
      <visual name='lidar_visual'>
        <geometry>
          <cylinder>
            <radius>0.0550</radius>
            <length>0.0315</length>
          </cylinder>
        </geometry>
        <material>
          <ambient> 1 0 1 </ambient>
          <diffuse> 1 0 1 </diffuse>
          <specular> 0.1 0.1 0.1 1 1 </specular>
        </material>
      </visual>

      <collision name='lidar_collision'>
        <geometry>
          <cylinder>
            <radius>0.0550</radius>
            <length>0.0315</length>
          </cylinder>
        </geometry>
      </collision>

      <inertial>
        <pose>0 0 0 0 0 0</pose>
        <mass>0.114</mass>
        <inertia>
          <ixx>0.001</ixx>
          <iyy>0.001</iyy>
          <izz>0.001</izz>
        </inertia>
      </inertial>

      <sensor type="ray" name="laser_16">
        <pose>0 0 0 0 0 0</pose>
        <always_on>true</always_on>
        <visualize>false</visualize>
        <update_rate>10</update_rate>
        <ray>
          <scan>
            <horizontal>
              <samples>180</samples>
              <resolution>1</resolution>
              <min_angle>-3.1415</min_angle>
              <max_angle>3.1415</max_angle>
            </horizontal>
            <vertical>
              <samples>16</samples>
              <resolution>1</resolution>
              <min_angle>-0.2618</min_angle>
              <max_angle>0.2618</max_angle>
            </vertical>
          </scan>
          <range>
            <min>0.2</min>
            <max>10.0</max>
            <resolution>0.02</resolution>
          </range>
          <noise>
            <type>gaussian</type>
            <mean>0.0</mean>
            <stddev>0.0</stddev>
          </noise>
        </ray>
        <!-- sensor plugin for lidar -->
        <plugin name="lidar_sensor" filename="libgazebo_ros_velodyne_laser.so">
          <robotNamespace>tergeo</robotNamespace>
          <topicName>/sensor/lidar16/top/pointcloud</topicName>
          <frameName>top_lidar16_link</frameName>
          <min_range>0.2</min_range>
          <max_range>10.0</max_range>
          <!-- <min_intensity>0.001</min_intensity> -->
          <gaussianNoise>0.02</gaussianNoise>
        </plugin>
      </sensor>
    </link>

    <!-- imu joint -->
    <joint name='imu_joint' type='fixed'>
      <parent>base_link</parent>
      <child>imu_link</child>
    </joint>

    <!-- imu link -->
    <link name='imu_link'>
      <pose>-0.032 0 0.068 0 0 0</pose>
      <visual name='imu_visual'>
        <geometry>
          <cylinder>
            <radius>0.01</radius>
            <length>0.005</length>
          </cylinder>
        </geometry>
        <material>
          <ambient> 0 0 1 </ambient>
          <diffuse> 0 0 1 </diffuse>
          <specular> 0.1 0.1 0.1 1 1 </specular>
        </material>
      </visual>
      
      <collision name='imu_collision'>
        <geometry>
          <cylinder>
            <radius>0.01</radius>
            <length>0.005</length>
          </cylinder>
        </geometry>
      </collision>

      <inertial>
        <pose>0 0 0 0 0 0</pose>
        <mass>0.01</mass>
        <inertia>
          <ixx>0.001</ixx>
          <iyy>0.001</iyy>
          <izz>0.001</izz>
        </inertia>
      </inertial>

      <sensor type="imu" name='imu_sensor'>
        <always_on>true</always_on>
        <visualize>false</visualize>
        <imu>
          <linear_acceleration>
            <x>
              <noise type='gaussian'>
                <mean>0.0</mean>
                <stddev>2e-4</stddev>
                <bias_mean>0.0000075</bias_mean>
                <bias_stddev>0.0000008</bias_stddev>
              </noise>
            </x>
          </linear_acceleration>
        </imu>

        <plugin name="imu_plugin" filename="libgazebo_ros_imu_sensor.so">
          <topicName>/sensor/imu/center/pose</topicName>
          <bodyName>imu_link</bodyName>
          <frameName>imu_link</frameName>
          <serviceName>imu_service</serviceName>
          <gaussianNoise>0.0</gaussianNoise>
          <updateRateHZ>60</updateRateHZ>
          <xyzOffset>0 0 0</xyzOffset>
          <rpyOffset>0 0 0</rpyOffset>
        </plugin>
      </sensor>
    </link>

    <!-- sonar template -->
    <!-- sonar 01 joint -->
    <!-- <joint name='sonar_01_joint' type='fixed'>
      <parent>base_link</parent>
      <child>sonar_01_link</child>
    </joint> -->

    <!-- sonar 01 link -->
    <!-- <link name='sonar_01_link'>
      <pose>0.45 0.0 0.9 0 0 0</pose>
      <visual name='sonar_01_visual'>
        <geometry>
          <box>
            <size>0.01 0.01 0.01</size>
          </box>
        </geometry>
      </visual>

      <collision name='sonar_01_collision'>
        <geometry>
          <box>
            <size>0.01 0.01 0.01</size>
          </box>
        </geometry>
      </collision>

      <inertial>
        <pose>0 0 0 0 0 0</pose>
        <mass>0.0001</mass>
        <inertia>
          <ixx>0</ixx>
          <iyy>0</iyy>
          <izz>0</izz>
        </inertia>
      </inertial>

      <sensor type="ray" name="left_sonar_sensor">
        <pose>0 0 0 0 0 0</pose>
        <visualize>true</visualize>
        <update_rate>5</update_rate>
        <ray>
          <scan>
            <horizontal>
              <samples>5</samples>
              <resolution>1.0</resolution>
              <min_angle>-0.1309</min_angle>
              <max_angle>0.1309</max_angle>
            </horizontal>
            <vertical>
              <samples>5</samples>
              <resolution>1</resolution>
              <min_angle>-0.1309</min_angle>
              <max_angle>0.1309</max_angle>
            </vertical>
          </scan>
          <range>
            <min>0.1</min>
            <max>0.3</max>
            <resolution>0.01</resolution>
          </range>
        </ray> -->
        <!-- sensor plugin for sonar -->
        <!-- <plugin name="sonar_01_plugin" filename="libgazebo_ros_range.so">
          <gaussianNoise>0.005</gaussianNoise>
          <alwaysOn>true</alwaysOn>
          <updateRate>5</updateRate>
          <topicName>/sensor/sonar/front/range</topicName>
          <frameName>sonar_01_link</frameName>
          <fov>0.2618</fov>
          <radiation>ultrasound</radiation>
        </plugin>
      </sensor>

    </link> -->
  </model>
</sdf>